Workbook

Sheet REPORTE DIARIO DE OPERACIONES
A2: Fecha | B2: Cuenca | C2: Campo | D2: Contratista | E2: Unidad | F2: TAG de la unidad | G2: capacidad instalada | H2: Capacidad Entregada (kW) | I2: Horometro inicial | J2: Horometro final | K2: KWH generados | L2: Potencia promedio | M2: Horas Operacion | N2: Horas StandBy | O2: Horas MMT Preventivo | P2: Horas MMT Correctivo | Q2: total horas | R2: Horas Paradas Externas | S2: Numero de fallas | T2: Tipo de combustible Primario | U2: Tipo de combustible Secundario | V2: Consumo de combustible Primario | W2: Consumo de combustible secundario | X2: Eficiencia | Y2: Observaciones
A3: 46235 | B3: PUTN | C3: COSTAYACO | D3: COPOWER | E3: J320 | F3: CPW-01 | G3: 1050 | H3: 700 | I3: 16215 | J3: 16239 | K3: 14497 | L3: 604.04167 | M3: 24 | N3: 0 | O3: 0 | P3: 0 | Q3: 24 | R3: 0 | S3: 0 | T3: GAS | U3: NO APLICA | V3: 127574 | W3: NO APLICA | X3: 1
A4: 46235 | B4: PUTN | C4: COSTAYACO | D4: COPOWER | E4: J320 | F4: CPW-02 | G4: 1050 | H4: 700 | I4: 14045 | J4: 14045 | K4: 0 | L4: 0 | M4: 0 | N4: 24 | O4: 0 | P4: 0 | Q4: 24 | R4: 0 | S4: 0 | T4: GAS | U4: NO APLICA | V4: 0 | W4: NO APLICA | X4: 1 | Y4: 24 horas de stand by por trabajos en linea de gas moqueta
A5: 46235 | B5: PUTN | C5: COSTAYACO | D5: COPOWER | E5: J320 | F5: CPW-03 | G5: 1050 | H5: 700 | I5: 12472 | J5: 12496 | K5: 14497 | L5: 604.04167 | M5: 24 | N5: 0 | O5: 0 | P5: 0 | Q5: 24 | R5: 0 | S5: 0 | T5: GAS | U5: NO APLICA | V5: 127574 | W5: NO APLICA | X5: 1
A6: 46235 | B6: PUTN | C6: COSTAYACO | D6: COPOWER | E6: J420 | F6: CPW-04 | G6: 1300 | H6: 1040 | I6: 3934 | J6: 3934 | K6: 0 | L6: 0 | M6: 0 | N6: 24 | O6: 0 | P6: 0 | Q6: 24 | R6: 0 | S6: 0 | T6: GAS | U6: NO APLICA | V6: 0 | W6: NO APLICA | X6: 1 | Y6: 24 horas de stand by por trabajos en linea de gas moqueta
A7: 46235 | B7: PUTN | C7: COSTAYACO | D7: COPOWER | E7: J420 | F7: CPW-05 | G7: 1300 | H7: 1040 | I7: 3927 | J7: 3927 | K7: 0 | L7: 0 | M7: 0 | N7: 24 | O7: 0 | P7: 0 | Q7: 24 | R7: 0 | S7: 0 | T7: GAS | U7: NO APLICA | V7: 0 | W7: NO APLICA | X7: 1 | Y7: 24 horas de stand by por trabajos en linea de gas moqueta
A8: 46235 | B8: PUTN | C8: COSTAYACO | D8: COPOWER | E8: J420 | F8: CPW-06 | G8: 1300 | H8: 1040 | I8: 2369 | J8: 2393 | K8: 19335 | L8: 805.625 | M8: 24 | N8: 0 | O8: 0 | P8: 0 | Q8: 24 | R8: 0 | S8: 0 | T8: GAS | U8: NO APLICA | V8: 170148 | W8: NO APLICA | X8: 1
A9: 46235 | B9: PUTN | C9: COSTAYACO | D9: COPOWER | E9: J320 | F9: CPW-07 | G9: 1050 | H9: 740 | I9: 1341 | J9: 1365 | K9: 14011 | L9: 583.79167 | M9: 24 | N9: 0 | O9: 0 | P9: 0 | Q9: 24 | R9: 0 | S9: 0 | T9: GAS | U9: NO APLICA | V9: 123297 | W9: NO APLICA | X9: 1
A10: 46235 | B10: PUTN | C10: COSTAYACO | D10: COPOWER | E10: CUMMINS | F10: G101V | G10: 500 | H10: 360 | I10: 15228 | J10: 15228 | K10: 0 | L10: 0 | M10: 0 | N10: 24 | O10: 0 | P10: 0 | Q10: 24 | R10: 0 | S10: 0 | T10: DIESEL | U10: NO APLICA | V10: 0 | W10: NO APLICA | X10: 1
A11: 46235 | B11: PUTN | C11: COSTAYACO | D11: COPOWER | E11: CUMMINS | F11: G102J | G11: 1000 | H11: 800 | I11: 3531 | J11: 3531 | K11: 0 | L11: 0 | M11: 0 | N11: 24 | O11: 0 | P11: 0 | Q11: 24 | R11: 0 | S11: 0 | T11: DIESEL | U11: NO APLICA | V11: 0 | W11: NO APLICA | X11: 1
A12: 46235 | B12: PUTN | C12: COSTAYACO | D12: COPOWER | E12: CUMMINS | F12: G102K | G12: 1000 | H12: 800 | I12: 2406 | J12: 2406 | K12: 0 | L12: 0 | M12: 0 | N12: 24 | O12: 0 | P12: 0 | Q12: 24 | R12: 0 | S12: 0 | T12: DIESEL | U12: NO APLICA | V12: 0 | W12: NO APLICA | X12: 1
A13: 46235 | B13: PUTN | C13: VONU | D13: COPOWER | E13: JINAN | F13: JIN-01 | G13: 600 | H13: 350 | I13: 6385 | J13: 6409 | K13: 8406 | L13: 350.25 | M13: 24 | N13: 0 | O13: 0 | P13: 0 | Q13: 24 | R13: 0 | S13: 0 | T13: GAS | U13: NO APLICA | V13: 73973 | W13: NO APLICA | X13: 1
A14: 46235 | B14: PUTN | C14: VONU | D14: COPOWER | E14: JINAN | F14: JIN-02 | G14: 600 | H14: 350 | I14: 6295 | J14: 6319 | K14: 8397 | L14: 349.875 | M14: 24 | N14: 0 | O14: 0 | P14: 0 | Q14: 24 | R14: 0 | S14: 0 | T14: GAS | U14: NO APLICA | V14: 73894 | W14: NO APLICA | X14: 1
A15: 46235 | B15: PUTN | C15: COSTAYACO | D15: COPOWER | E15: JINAN | F15: CPW-10 | G15: 600 | H15: 450 | I15: 4373 | J15: 4391 | K15: 5831 | L15: 242.95833 | M15: 18 | N15: 6 | O15: 0 | P15: 0 | Q15: 24 | R15: 0 | S15: 0 | T15: GAS | U15: NO APLICA | V15: 51313 | W15: NO APLICA | X15: 1 | Y15: 00:23 ingresa en linea equipo CPW-10 a peticion de operador CCM y sale a las 3:01 por lluvias en la zona y controlar presion de gas CYC-----04:50 Ingresa en linea equipo CpW10 con gas CYC a pteticion de operador de CCM-----19:04 Sale de linea CPW-10 por peticion de operador de CCM.
A16: 46235 | B16: PUTN | C16: COSTAYACO | D16: COPOWER | E16: JINAN | F16: CPW-11 | G16: 600 | H16: 450 | I16: 516 | J16: 540 | K16: 8364 | L16: 348.5 | M16: 24 | N16: 0 | O16: 0 | P16: 0 | Q16: 24 | R16: 0 | S16: 0 | T16: GAS | U16: NO APLICA | V16: 73603 | W16: NO APLICA | X16: 1
A17: 46235 | B17: PUTN | C17: COSTAYACO | D17: COPOWER | E17: JINAN | F17: CPW-12 | G17: 600 | H17: 450 | I17: 651 | J17: 651 | K17: 0 | L17: 0 | M17: 0 | N17: 24 | O17: 0 | P17: 0 | Q17: 24 | R17: 0 | S17: 0 | T17: GAS | U17: NO APLICA | V17: 0 | W17: NO APLICA | X17: 1
A18: 46236 | B18: PUTN | C18: COSTAYACO | D18: COPOWER | E18: J320 | F18: CPW-01 | G18: 1050 | H18: 700 | I18: 16239 | J18: 16263 | K18: 14766 | L18: 615.25 | M18: 24 | N18: 0 | O18: 0 | P18: 0 | Q18: 24 | R18: 0 | S18: 0 | T18: GAS | U18: NO APLICA | V18: 129941 | W18: NO APLICA | X18: 1
A19: 46236 | B19: PUTN | C19: COSTAYACO | D19: COPOWER | E19: J320 | F19: CPW-02 | G19: 1050 | H19: 700 | I19: 14045 | J19: 14047 | K19: 1017 | L19: 42.375 | M19: 2 | N19: 22 | O19: 0 | P19: 0 | Q19: 24 | R19: 0 | S19: 0 | T19: GAS | U19: NO APLICA | V19: 8950 | W19: NO APLICA | X19: 1 | Y19: 18:00 hrs. EQUIPO:CPW-02, A solicitud del CCM, Ingresan con gas Moqueta----19:54. EQUIPO:CPW-02, A solicitud del CCM, sale de linea para recuperar presion de gas moqueta 119 psi
A20: 46236 | B20: PUTN | C20: COSTAYACO | D20: COPOWER | E20: J320 | F20: CPW-03 | G20: 1050 | H20: 700 | I20: 12496 | J20: 12520 | K20: 14761 | L20: 615.04167 | M20: 24 | N20: 0 | O20: 0 | P20: 0 | Q20: 24 | R20: 0 | S20: 0 | T20: GAS | U20: NO APLICA | V20: 129897 | W20: NO APLICA | X20: 1
A21: 46236 | B21: PUTN | C21: COSTAYACO | D21: COPOWER | E21: J420 | F21: CPW-04 | G21: 1300 | H21: 1040 | I21: 3934 | J21: 3944 | K21: 7899 | L21: 329.125 | M21: 10 | N21: 14 | O21: 0 | P21: 0 | Q21: 24 | R21: 0 | S21: 0 | T21: GAS | U21: NO APLICA | V21: 69511 | W21: NO APLICA | X21: 1 | Y21: 14:20 hrs. EQUIPO:CPW-04, A solicitud del CCM, Ingresan con gas Moqueta
A22: 46236 | B22: PUTN | C22: COSTAYACO | D22: COPOWER | E22: J420 | F22: CPW-05 | G22: 1300 | H22: 1040 | I22: 3927 | J22: 3936 | K22: 7668 | L22: 319.5 | M22: 9 | N22: 15 | O22: 0 | P22: 0 | Q22: 24 | R22: 0 | S22: 0 | T22: GAS | U22: NO APLICA | V22: 67478 | W22: NO APLICA | X22: 1 | Y22: 14:42 hrs. EQUIPO:CPW-05, A solicitud del CCM, Ingresan con gas Moqueta
A23: 46236 | B23: PUTN | C23: COSTAYACO | D23: COPOWER | E23: J420 | F23: CPW-06 | G23: 1300 | H23: 1040 | I23: 2393 | J23: 2417 | K23: 19533 | L23: 813.875 | M23: 24 | N23: 0 | O23: 0 | P23: 0 | Q23: 24 | R23: 0 | S23: 0 | T23: GAS | U23: NO APLICA | V23: 171890 | W23: NO APLICA | X23: 1
A24: 46236 | B24: PUTN | C24: COSTAYACO | D24: COPOWER | E24: J320 | F24: CPW-07 | G24: 1050 | H24: 740 | I24: 1365 | J24: 1389 | K24: 14313 | L24: 596.375 | M24: 24 | N24: 0 | O24: 0 | P24: 0 | Q24: 24 | R24: 0 | S24: 0 | T24: GAS | U24: NO APLICA | V24: 125954 | W24: NO APLICA | X24: 1
A25: 46236 | B25: PUTN | C25: COSTAYACO | D25: COPOWER | E25: CUMMINS | F25: G101V | G25: 500 | H25: 360 | I25: 15228 | J25: 15228 | K25: 0 | L25: 0 | M25: 0 | N25: 24 | O25: 0 | P25: 0 | Q25: 24 | R25: 0 | S25: 0 | T25: DIESEL | U25: NO APLICA | V25: 0 | W25: NO APLICA | X25: 1
A26: 46236 | B26: PUTN | C26: COSTAYACO | D26: COPOWER | E26: CUMMINS | F26: G102J | G26: 1000 | H26: 800 | I26: 3531 | J26: 3533 | K26: 2159 | L26: 89.958333 | M26: 2 | N26: 22 | O26: 0 | P26: 0 | Q26: 24 | R26: 0 | S26: 0 | T26: DIESEL | U26: NO APLICA | V26: 151 | W26: NO APLICA | X26: 1 | Y26: 8:24 EQUIPO:G102J, A solicitud del CCM, entran en linea. Por inicio de maniobras para pasar equipos de reparto de carga a carga base para cambio de control de frontera
A27: 46236 | B27: PUTN | C27: COSTAYACO | D27: COPOWER | E27: CUMMINS | F27: G102K | G27: 1000 | H27: 800 | I27: 2406 | J27: 2409 | K27: 2166 | L27: 90.25 | M27: 3 | N27: 21 | O27: 0 | P27: 0 | Q27: 24 | R27: 0 | S27: 0 | T27: DIESEL | U27: NO APLICA | V27: 152 | W27: NO APLICA | X27: 1 | Y27: 8:23 EQUIPO:G102K, A solicitud del CCM, entran en linea. Por inicio de maniobras para pasar equipos de reparto de carga a carga base para cambio de control de frontera
A28: 46236 | B28: PUTN | C28: VONU | D28: COPOWER | E28: JINAN | F28: JIN-01 | G28: 600 | H28: 350 | I28: 6409 | J28: 6433 | K28: 8399 | L28: 349.95833 | M28: 24 | N28: 0 | O28: 0 | P28: 0 | Q28: 24 | R28: 0 | S28: 0 | T28: GAS | U28: NO APLICA | V28: 73911 | W28: NO APLICA | X28: 1
A29: 46236 | B29: PUTN | C29: VONU | D29: COPOWER | E29: JINAN | F29: JIN-02 | G29: 600 | H29: 350 | I29: 6319 | J29: 6343 | K29: 8401 | L29: 350.04167 | M29: 24 | N29: 0 | O29: 0 | P29: 0 | Q29: 24 | R29: 0 | S29: 0 | T29: GAS | U29: NO APLICA | V29: 73929 | W29: NO APLICA | X29: 1
A30: 46236 | B30: PUTN | C30: COSTAYACO | D30: COPOWER | E30: JINAN | F30: CPW-10 | G30: 600 | H30: 450 | I30: 4391 | J30: 4391 | K30: 0 | L30: 0 | M30: 0 | N30: 24 | O30: 0 | P30: 0 | Q30: 24 | R30: 0 | S30: 0 | T30: GAS | U30: NO APLICA | V30: 0 | W30: NO APLICA | X30: 1 | Y30: POR PETICION D CCM BAJA PRESIÓN DE GAS
A31: 46236 | B31: PUTN | C31: COSTAYACO | D31: COPOWER | E31: JINAN | F31: CPW-11 | G31: 600 | H31: 450 | I31: 540 | J31: 564 | K31: 8479 | L31: 353.29167 | M31: 24 | N31: 0 | O31: 0 | P31: 0 | Q31: 24 | R31: 0 | S31: 0 | T31: GAS | U31: NO APLICA | V31: 74611 | W31: NO APLICA | X31: 1
A32: 46236 | B32: PUTN | C32: COSTAYACO | D32: COPOWER | E32: JINAN | F32: CPW-12 | G32: 600 | H32: 450 | I32: 651 | J32: 651 | K32: 0 | L32: 0 | M32: 0 | N32: 24 | O32: 0 | P32: 0 | Q32: 24 | R32: 0 | S32: 0 | T32: GAS | U32: NO APLICA | V32: 0 | W32: NO APLICA | X32: 1 | Y32: POR PETICION D CCM BAJA PRESIÓN DE GAS
A33: 46237 | B33: PUTN | C33: COSTAYACO | D33: COPOWER | E33: J320 | F33: CPW-01 | G33: 1050 | H33: 700 | I33: 16263 | J33: 16283 | K33: 13376 | L33: 557.33333 | M33: 20 | N33: 4 | O33: 0 | P33: 0 | Q33: 24 | R33: 0 | S33: 0 | T33: GAS | U33: NO APLICA | V33: 117709 | W33: NO APLICA | X33: 1 | Y33: 10:17 hrs. Generador CPW01 parada manual a solicitud de CCM por parada de MRU por cambio de filtros, 12:32 hrs. Equipo ingresa en linea con gas MRU-----22:44 Sale de linea equipo CPW-01 por salida de MRU
A34: 46237 | B34: PUTN | C34: COSTAYACO | D34: COPOWER | E34: J320 | F34: CPW-02 | G34: 1050 | H34: 700 | I34: 14047 | J34: 14057 | K34: 6521 | L34: 271.70833 | M34: 10 | N34: 14 | O34: 0 | P34: 0 | Q34: 24 | R34: 0 | S34: 0 | T34: GAS | U34: NO APLICA | V34: 57385 | W34: NO APLICA | X34: 1 | Y34: 12:43 hrs. Generador CPW02 ingresa a linea a solicitud de CCM con gas MRU-----22:44 Sale de linea equipo CPW-02 por salida de MRU
A35: 46237 | B35: PUTN | C35: COSTAYACO | D35: COPOWER | E35: J320 | F35: CPW-03 | G35: 1050 | H35: 700 | I35: 12520 | J35: 12530 | K35: 6799 | L35: 283.29167 | M35: 10 | N35: 14 | O35: 0 | P35: 0 | Q35: 24 | R35: 0 | S35: 0 | T35: GAS | U35: NO APLICA | V35: 59831 | W35: NO APLICA | X35: 1 | Y35: 12:43 hrs. Generador CPW02 ingresa a linea a solicitud de CCM con gas MRU-----22:44 Sale de linea equipo CPW-02 por salida de MRU
A36: 46237 | B36: PUTN | C36: COSTAYACO | D36: COPOWER | E36: J420 | F36: CPW-04 | G36: 1300 | H36: 1040 | I36: 3944 | J36: 3968 | K36: 20730 | L36: 863.75 | M36: 24 | N36: 0 | O36: 0 | P36: 0 | Q36: 24 | R36: 0 | S36: 0 | T36: GAS | U36: NO APLICA | V36: 182424 | W36: NO APLICA | X36: 1
A37: 46237 | B37: PUTN | C37: COSTAYACO | D37: COPOWER | E37: J420 | F37: CPW-05 | G37: 1300 | H37: 1040 | I37: 3936 | J37: 3960 | K37: 20558 | L37: 856.58333 | M37: 24 | N37: 0 | O37: 0 | P37: 0 | Q37: 24 | R37: 0 | S37: 0 | T37: GAS | U37: NO APLICA | V37: 180910 | W37: NO APLICA | X37: 1
A38: 46237 | B38: PUTN | C38: COSTAYACO | D38: COPOWER | E38: J420 | F38: CPW-06 | G38: 1300 | H38: 1040 | I38: 2417 | J38: 2438 | K38: 17807 | L38: 741.95833 | M38: 21 | N38: 3 | O38: 0 | P38: 0 | Q38: 24 | R38: 0 | S38: 0 | T38: GAS | U38: NO APLICA | V38: 156702 | W38: NO APLICA | X38: 1 | Y38: 10:32 hrs. Generador CPW06 parada manual a solicitud de CCM por parada de MRU por cambio de filtros, 12:50 hrs. Equipo ingresa en linea con gas MRU----22:44 Sale de linea equipo CPW-06 por salida de MRU
A39: 46237 | B39: PUTN | C39: COSTAYACO | D39: COPOWER | E39: J320 | F39: CPW-07 | G39: 1050 | H39: 740 | I39: 1389 | J39: 1410 | K39: 12724 | L39: 530.16667 | M39: 21 | N39: 3 | O39: 0 | P39: 0 | Q39: 24 | R39: 0 | S39: 0 | T39: GAS | U39: NO APLICA | V39: 111971 | W39: NO APLICA | X39: 1 | Y39: 22:44 Sale de linea equipo CPW-07 por salida de MRU
A40: 46237 | B40: PUTN | C40: COSTAYACO | D40: COPOWER | E40: CUMMINS | F40: G101V | G40: 500 | H40: 360 | I40: 15228 | J40: 15231 | K40: 1007 | L40: 41.958333 | M40: 3 | N40: 21 | O40: 0 | P40: 0 | Q40: 24 | R40: 0 | S40: 0 | T40: DIESEL | U40: NO APLICA | V40: 70 | W40: NO APLICA | X40: 1 | Y40: 10:12hrs. Generador G101V ingresa a linea a solicitud de CCM por salida de generacion asociada a la MRU, 13:00hrs sale de linea a solicitud de CCM
A41: 46237 | B41: PUTN | C41: COSTAYACO | D41: COPOWER | E41: CUMMINS | F41: G102J | G41: 1000 | H41: 800 | I41: 3533 | J41: 3537 | K41: 2679 | L41: 111.625 | M41: 4 | N41: 20 | O41: 0 | P41: 0 | Q41: 24 | R41: 0 | S41: 0 | T41: DIESEL | U41: NO APLICA | V41: 188 | W41: NO APLICA | X41: 1 | Y41: 10:10hrs. Generador G102J ingresa a linea a solicitud de CCM por salida de generacion asociada a la MRU, 12:56hrs sale de linea a solicitud de CCM
...

Sheet Hoja1
A2: Tipo de combustible Primario | B2: (Todas) | C2: Horas Totales Junio | D2: 744 | N2: Tiempo medio falla | O2: Tiempo medio Reparación
L3: #VALUE!
A4: Etiquetas de fila | B4: Suma de Horas Operacion | C4: Suma de Horas StandBy | D4: Suma de Numero de fallas | E4: Suma de Horas MMT Preventivo | F4: Suma de Horas MMT Correctivo | G4: Suma de total horas | H4: Suma de KWH generados | I4: Suma de Horas Paradas Externas | J4: Suma de Consumo de combustible Primario | K4: Promedio de KWH generados2 | L4: Calculo de disponibilidad utilizando horas operacionales y de standby | M4: Confiabilidad | N4: MTBF | O4: MTTR | P4: DISPONIBILIDAD TENIENDO ENCUENTA MMT PREVENTIVOS Y MMT CORRECTIVOS
A5: CPW-01 | B5: 465 | C5: 57 | D5: 0 | E5: 6 | F5: 0 | G5: 528 | H5: 292328 | I5: 43 | J5: 2572487.2 | K5: 13287.636 | L5: =(SUM(B5:C5)/GETPIVOTDATA("Suma de total horas",$A$4,"TAG de la unidad",A5)) -> 0.98863636 | M5: =IFERROR(EXP((-1/N5)*1.6),1) -> 1 | N5: =IFERROR(((G5-E5-F5-C5)/D5),0) -> 0 | O5: =IFERROR(F5/D5,0) -> 0 | P5: =((G5-(E5+F5))/G5) -> 0.98863636
A6: CPW-02 | B6: 386 | C6: 142 | D6: 0 | E6: 0 | F6: 0 | G6: 528 | H6: 243012 | I6: 38 | J6: 2138505.6 | K6: 11046 | L6: =(SUM(B6:C6)/GETPIVOTDATA("Suma de total horas",$A$4,"TAG de la unidad",A6)) -> 1 | M6: =IFERROR(EXP((-1/N6)*1.6),1) -> 1 | N6: =IFERROR(((G6-E6-F6-C6)/D6),0) -> 0 | O6: =IFERROR(F6/D6,0) -> 0 | P6: =((G6-(E6+F6))/G6) -> 1
A7: CPW-03 | B7: 459 | C7: 62 | D7: 0 | E7: 7 | F7: 0 | G7: 528 | H7: 287674 | I7: 24 | J7: 2531532.6 | K7: 13076.091 | L7: =(SUM(B7:C7)/GETPIVOTDATA("Suma de total horas",$A$4,"TAG de la unidad",A7)) -> 0.98674242 | M7: =IFERROR(EXP((-1/N7)*1.6),1) -> 1 | N7: =IFERROR(((G7-E7-F7-C7)/D7),0) -> 0 | O7: =IFERROR(F7/D7,0) -> 0 | P7: =((G7-(E7+F7))/G7) -> 0.98674242
A8: CPW-04 | B8: 453 | C8: 75 | D8: 0 | E8: 0 | F8: 0 | G8: 528 | H8: 342171 | I8: 5 | J8: 3011104.8 | K8: 15553.227 | L8: =(SUM(B8:C8)/GETPIVOTDATA("Suma de total horas",$A$4,"TAG de la unidad",A8)) -> 1 | M8: =IFERROR(EXP((-1/N8)*1.6),1) -> 1 | N8: =IFERROR(((G8-E8-F8-C8)/D8),0) -> 0 | O8: =IFERROR(F8/D8,0) -> 0 | P8: =((G8-(E8+F8))/G8) -> 1
A9: CPW-05 | B9: 474 | C9: 54 | D9: 0 | E9: 0 | F9: 0 | G9: 528 | H9: 366816 | I9: 14 | J9: 3227981.4 | K9: 16673.455 | L9: =(SUM(B9:C9)/GETPIVOTDATA("Suma de total horas",$A$4,"TAG de la unidad",A9)) -> 1 | M9: =IFERROR(EXP((-1/N9)*1.6),1) -> 1 | N9: =IFERROR(((G9-E9-F9-C9)/D9),0) -> 0 | O9: =IFERROR(F9/D9,0) -> 0 | P9: =((G9-(E9+F9))/G9) -> 1
A10: CPW-06 | B10: 441 | C10: 79 | D10: 0 | E10: 8 | F10: 0 | G10: 528 | H10: 338404 | I10: 41 | J10: 2977955.2 | K10: 15382 | L10: =(SUM(B10:C10)/GETPIVOTDATA("Suma de total horas",$A$4,"TAG de la unidad",A10)) -> 0.98484848 | M10: =IFERROR(EXP((-1/N10)*1.6),1) -> 1 | N10: =IFERROR(((G10-E10-F10-C10)/D10),0) -> 0 | O10: =IFERROR(F10/D10,0) -> 0 | P10: =((G10-(E10+F10))/G10) -> 0.98484848
A11: CPW-07 | B11: 480 | C11: 42 | D11: 0 | E11: 6 | F11: 0 | G11: 528 | H11: 284496 | I11: 21 | J11: 2503564.8 | K11: 12931.636 | L11: =(SUM(B11:C11)/GETPIVOTDATA("Suma de total horas",$A$4,"TAG de la unidad",A11)) -> 0.98863636 | M11: =IFERROR(EXP((-1/N11)*1.6),1) -> 1 | N11: =IFERROR(((G11-E11-F11-C11)/D11),0) -> 0 | O11: =IFERROR(F11/D11,0) -> 0 | P11: =((G11-(E11+F11))/G11) -> 0.98863636
A12: CPW-10 | B12: 392 | C12: 128 | D12: 0 | E12: 8 | F12: 0 | G12: 528 | H12: 143331 | I12: 54 | J12: 1261312.2 | K12: 6515.0455 | L12: =(SUM(B12:C12)/GETPIVOTDATA("Suma de total horas",$A$4,"TAG de la unidad",A12)) -> 0.98484848 | M12: =IFERROR(EXP((-1/N12)*1.6),1) -> 1 | N12: =IFERROR(((G12-E12-F12-C12)/D12),0) -> 0 | O12: =IFERROR(F12/D12,0) -> 0 | P12: =((G12-(E12+F12))/G12) -> 0.98484848
A13: CPW-11 | B13: 456 | C13: 65 | D13: 0 | E13: 7 | F13: 0 | G13: 528 | H13: 166590 | I13: 39 | J13: 1465987.4 | K13: 7572.2727 | L13: =(SUM(B13:C13)/GETPIVOTDATA("Suma de total horas",$A$4,"TAG de la unidad",A13)) -> 0.98674242 | M13: =IFERROR(EXP((-1/N13)*1.6),1) -> 1 | N13: =IFERROR(((G13-E13-F13-C13)/D13),0) -> 0 | O13: =IFERROR(F13/D13,0) -> 0 | P13: =((G13-(E13+F13))/G13) -> 0.98674242
A14: CPW-12 | B14: 295 | C14: 225 | D14: 0 | E14: 8 | F14: 0 | G14: 528 | H14: 104796 | I14: 78 | J14: 922206 | K14: 4763.4545 | L14: =(SUM(B14:C14)/GETPIVOTDATA("Suma de total horas",$A$4,"TAG de la unidad",A14)) -> 0.98484848 | M14: =IFERROR(EXP((-1/N14)*1.6),1) -> 1 | N14: =IFERROR(((G14-E14-F14-C14)/D14),0) -> 0 | O14: =IFERROR(F14/D14,0) -> 0 | P14: =((G14-(E14+F14))/G14) -> 0.98484848
A15: G101V | B15: 110 | C15: 418 | D15: 0 | E15: 0 | F15: 0 | G15: 528 | H15: 38427 | I15: 0 | J15: 2123 | K15: 1746.6818 | L15: =(SUM(B15:C15)/GETPIVOTDATA("Suma de total horas",$A$4,"TAG de la unidad",A15)) -> 1 | M15: =IFERROR(EXP((-1/N15)*1.6),1) -> 1 | N15: =IFERROR(((G15-E15-F15-C15)/D15),0) -> 0 | O15: =IFERROR(F15/D15,0) -> 0 | P15: =((G15-(E15+F15))/G15) -> 1
A16: G102J | B16: 110 | C16: 418 | D16: 0 | E16: 0 | F16: 0 | G16: 528 | H16: 85209 | I16: 0 | J16: 5294 | K16: 3873.1364 | L16: =(SUM(B16:C16)/GETPIVOTDATA("Suma de total horas",$A$4,"TAG de la unidad",A16)) -> 1 | M16: =IFERROR(EXP((-1/N16)*1.6),1) -> 1 | N16: =IFERROR(((G16-E16-F16-C16)/D16),0) -> 0 | O16: =IFERROR(F16/D16,0) -> 0 | P16: =((G16-(E16+F16))/G16) -> 1
... A19: JIN-02 | B19: 508 | C19: 13 | D19: 0 | E19: 7 | F19: 0 | G19: 528 | H19: 175295 | I19: 0 | J19: 1542596.2 | K19: 7967.9545 | L19: =(SUM(B19:C19)/GETPIVOTDATA("Suma de total horas",$A$4,"TAG de la unidad",A19)) -> 0.98674242 | M19: =IFERROR(EXP((-1/N19)*1.6),1) -> 1 | N19: =IFERROR(((G19-E19-F19-C19)/D19),0) -> 0 | O19: =IFERROR(F19/D19,0) -> 0 | P19: =((G19-(E19+F19))/G19) -> 0.98674242
A20: Total general | B20: 5638 | C20: 2209 | D20: 0 | E20: 73 | F20: 0 | G20: 7920 | H20: 3135033 | I20: 374 | J20: 25707371 | K20: 9500.1 | M20: =IFERROR(EXP((-1/N20)*1.6),1) -> 1 | N20: =IFERROR(((G20-E20-F20-C20)/D20),0) -> 0 | O20: =IFERROR(F20/D20,0) -> 0
E22: =SUM(B5:C5)/GETPIVOTDATA("Suma de total horas",$A$4,"TAG de la unidad","CPW-01") -> 0.98863636
E23: =SUM(B6:C6)/GETPIVOTDATA("Suma de total horas",$A$4,"TAG de la unidad","CPW-01") -> 1
B24: =GETPIVOTDATA("Suma de Horas Operacion ",$A$4)/GETPIVOTDATA("Suma de total horas",$A$4) -> 0.71186869 | E24: =SUM(B7:C7)/GETPIVOTDATA("Suma de total horas",$A$4,"TAG de la unidad","CPW-01") -> 0.98674242 | K24: promedio
B25: =GETPIVOTDATA("Suma de Horas StandBy",$A$4)/GETPIVOTDATA("Suma de total horas",$A$4) -> 0.27891414 | E25: =SUM(B8:C8)/GETPIVOTDATA("Suma de total horas",$A$4,"TAG de la unidad","CPW-01") -> 1
B26: =GETPIVOTDATA("Suma de Horas MMT Preventivo",$A$4)/GETPIVOTDATA("Suma de total horas",$A$4) -> 0.0092171717

Sheet Dashboard
A1: 📊 DASHBOARD DE GENERACIÓN - INDICADORES OPERATIVOS | JULIO 2026
A3: 🔑 KPIs BÁSICOS OPERATIVOS | H3: ⚙️ KPIs AVANZADOS DE CONFIABILIDAD | R3: 📋 RESUMEN EJECUTIVO - MAYO 2026
A5: Total KWH | B5: Horas Operación | C5: Horas StandBy | D5: Disponibilidad (%) | E5: Total Fallas | F5: Hrs MMT Total | H5: MTBF (Hrs) | I5: MTTR (Hrs) | J5: Confiabilidad (%) | K5: Indisponibilidad (%) | L5: % Unid. c/Fallas | R5: 🔍 PANORAMA GENERAL
A6: =Hoja1!H19 -> 175295 | B6: =Hoja1!B19 -> 508 | C6: =Hoja1!C19 -> 13 | D6: =Hoja1!B20/Hoja1!G20 -> 0.71186869 | E6: =Hoja1!D19 -> 0 | F6: =Hoja1!F19 -> 0 | H6: =(GETPIVOTDATA("Suma de total horas",Hoja1!$A$4)-GETPIVOTDATA("Suma de Horas StandBy",Hoja1!$A$4)-GETPIVOTDATA("Suma de Horas MMT Preventivo",Hoja1!$A$4)-GETPIVOTDATA("Suma de Horas MMT Correctivo",Hoja1!$A$4))/GETPIVOTDATA("Suma de Numero de fallas",Hoja1!$A$4) -> #DIV/0! | I6: =IF(Hoja1!D19>0,Hoja1!F19/Hoja1!D19,"N/A") -> N/A | J6: =COUNTIF(Hoja1!D5:D19,0)/COUNT(Hoja1!D5:D19) -> 1 | K6: =1-D6 -> 0.28813131 | L6: =COUNTIF(Hoja1!D5:D20,">0")/COUNT(Hoja1!D5:D20) -> 0 | R6: • Período: Mayo 2026 (31 días)
R7: • Flota: 16 unidades de generación
A8: 📋 INDICADORES POR UNIDAD | K8: 📊 RESUMEN POR TIPO DE UNIDAD | R8: • Generación total: 4,056,740 KWH
R9: • Disponibilidad global: 57.3%
A10: Unidad | B10: KWH Generados | C10: Hrs Operación | D10: Hrs StandBy | E10: Disponibilidad | F10: Fallas | G10: Hrs MMT Prev | H10: Hrs MMT Corr | I10: % del Total KWH | K10: Tipo Unidad | L10: Cantidad | M10: KWH Total | N10: Hrs Op Total | O10: Disp. Prom | P10: % Generación
A11: =Hoja1!A5 -> CPW-01 | B11: =Hoja1!H5 -> 292328 | C11: =Hoja1!B5 -> 465 | D11: =Hoja1!C5 -> 57 | E11: =Hoja1!L5 -> 0.98863636 | F11: =Hoja1!D5 -> 0 | G11: =Hoja1!E5 -> 6 | H11: =Hoja1!F5 -> 0 | I11: =Hoja1!H5/Hoja1!$H$20 -> 0.093245589 | K11: CPW (J320/J420) | L11: =COUNTIF(Hoja1!A5:A22,"CPW*") -> 10 | M11: =SUMIF(Hoja1!A5:A22,"CPW*",Hoja1!H5:H22) -> 2569618 | N11: =SUMIF(Hoja1!A5:A22,"CPW*",Hoja1!B5:B22) -> 4301 | O11: =SUMIF(Hoja1!A5:A22,"CPW*",Hoja1!B5:B22)/SUMIF(Hoja1!A5:A22,"CPW*",Hoja1!G5:G22) -> 0.81458333 | P11: =M11/Hoja1!$H$20 -> 0.81964624 | R11: 🎯 HALLAZGOS CLAVE
A12: =Hoja1!A6 -> CPW-02 | B12: =Hoja1!H6 -> 243012 | C12: =Hoja1!B6 -> 386 | D12: =Hoja1!C6 -> 142 | E12: =Hoja1!L6 -> 1 | F12: =Hoja1!D6 -> 0 | G12: =Hoja1!E6 -> 0 | H12: =Hoja1!F6 -> 0 | I12: =Hoja1!H6/Hoja1!$H$20 -> 0.077514974 | K12: CUMMINS (G10x) | L12: =COUNTIF(Hoja1!A6:A23,"G10*") -> 3 | M12: =SUMIF(Hoja1!A6:A22,"G10*",Hoja1!H6:H22) -> 215166 | N12: =SUMIF(Hoja1!A6:A22,"G10*",Hoja1!B6:B22) -> 340 | O12: =SUMIF(Hoja1!A6:A22,"G10*",Hoja1!B6:B22)/SUMIF(Hoja1!A6:A22,"G10*",Hoja1!G6:G22) -> 0.21464646 | P12: =M12/Hoja1!$H$20 -> 0.06863277
A13: =Hoja1!A7 -> CPW-03 | B13: =Hoja1!H7 -> 287674 | C13: =Hoja1!B7 -> 459 | D13: =Hoja1!C7 -> 62 | E13: =Hoja1!L7 -> 0.98674242 | F13: =Hoja1!D7 -> 0 | G13: =Hoja1!E7 -> 7 | H13: =Hoja1!F7 -> 0 | I13: =Hoja1!H7/Hoja1!$H$20 -> 0.091761076 | K13: JINAN (JIN) | L13: =COUNTIF(Hoja1!A7:A24,"JIN*") -> 2 | M13: =SUMIF(Hoja1!A7:A24,"JIN*",Hoja1!H7:H24) -> 350249 | N13: =SUMIF(Hoja1!A7:A24,"JIN*",Hoja1!B7:B24) -> 997 | O13: =SUMIF(Hoja1!A7:A24,"JIN*",Hoja1!B7:B24)/SUMIF(Hoja1!A7:A24,"JIN*",Hoja1!G7:G24) -> 0.94412879 | P13: =M13/Hoja1!$H$20 -> 0.11172099 | R13: ✅ FORTALEZAS:
A14: =Hoja1!A8 -> CPW-04 | B14: =Hoja1!H8 -> 342171 | C14: =Hoja1!B8 -> 453 | D14: =Hoja1!C8 -> 75 | E14: =Hoja1!L8 -> 1 | F14: =Hoja1!D8 -> 0 | G14: =Hoja1!E8 -> 0 | H14: =Hoja1!F8 -> 0 | I14: =Hoja1!H8/Hoja1!$H$20 -> 0.10914431 | K14: TOTAL | L14: =SUM(L11:L13) -> 15 | M14: =SUM(M11:M13) -> 3135033 | N14: =SUM(N11:N13) -> 5638 | O14: =AVERAGE(O11:O13) -> 0.6577862 | P14: =SUM(P11:P13) -> 1 | R14: • CPW aporta ~79% de la generación
A15: =Hoja1!A9 -> CPW-05 | B15: =Hoja1!H9 -> 366816 | C15: =Hoja1!B9 -> 474 | D15: =Hoja1!C9 -> 54 | E15: =Hoja1!L9 -> 1 | F15: =Hoja1!D9 -> 0 | G15: =Hoja1!E9 -> 0 | H15: =Hoja1!F9 -> 0 | I15: =Hoja1!H9/Hoja1!$H$20 -> 0.11700547 | R15: • 81% unidades sin fallas (13/16)
A16: =Hoja1!A10 -> CPW-06 | B16: =Hoja1!H10 -> 338404 | C16: =Hoja1!B10 -> 441 | D16: =Hoja1!C10 -> 79 | E16: =Hoja1!L10 -> 0.98484848 | F16: =Hoja1!D10 -> 0 | G16: =Hoja1!E10 -> 8 | H16: =Hoja1!F10 -> 0 | I16: =Hoja1!H10/Hoja1!$H$20 -> 0.10794272 | K16: 📍 RESUMEN POR CAMPO | R16: • MTBF excelente: 2,141 hrs
A17: =Hoja1!A11 -> CPW-07 | B17: =Hoja1!H11 -> 284496 | C17: =Hoja1!B11 -> 480 | D17: =Hoja1!C11 -> 42 | E17: =Hoja1!L11 -> 0.98863636 | F17: =Hoja1!D11 -> 0 | G17: =Hoja1!E11 -> 6 | H17: =Hoja1!F11 -> 0 | I17: =Hoja1!H11/Hoja1!$H$20 -> 0.09074737
A18: =Hoja1!A12 -> CPW-10 | B18: =Hoja1!H12 -> 143331 | C18: =Hoja1!B12 -> 392 | D18: =Hoja1!C12 -> 128 | E18: =Hoja1!L12 -> 0.98484848 | F18: =Hoja1!D12 -> 0 | G18: =Hoja1!E12 -> 8 | H18: =Hoja1!F12 -> 0 | I18: =Hoja1!H12/Hoja1!$H$20 -> 0.045719136 | K18: Campo | L18: KWH Total | M18: Hrs Operación | N18: Fallas | O18: Disponibilidad | R18: ⚠️ ÁREAS DE MEJORA:
A19: =Hoja1!A13 -> CPW-11 | B19: =Hoja1!H13 -> 166590 | C19: =Hoja1!B13 -> 456 | D19: =Hoja1!C13 -> 65 | E19: =Hoja1!L13 -> 0.98674242 | F19: =Hoja1!D13 -> 0 | G19: =Hoja1!E13 -> 7 | H19: =Hoja1!F13 -> 0 | I19: =Hoja1!H13/Hoja1!$H$20 -> 0.053138197 | K19: COSTAYACO | L19: =SUMIF('REPORTE DIARIO DE OPERACIONES'!C:C,"COSTAYACO",'REPORTE DIARIO DE OPERACIONES'!K:K) -> 2784784 | M19: =SUMIF('REPORTE DIARIO DE OPERACIONES'!C:C,"COSTAYACO",'REPORTE DIARIO DE OPERACIONES'!M:M) -> 4641 | N19: =SUMIF('REPORTE DIARIO DE OPERACIONES'!C:C,"COSTAYACO",'REPORTE DIARIO DE OPERACIONES'!S:S) -> 0 | O19: =M19/SUMIF('REPORTE DIARIO DE OPERACIONES'!C:C,"COSTAYACO",'REPORTE DIARIO DE OPERACIONES'!Q:Q) -> 0.67613636 | R19: • CUMMINS solo 13.5% disponibilidad
A20: =Hoja1!A14 -> CPW-12 | B20: =Hoja1!H14 -> 104796 | C20: =Hoja1!B14 -> 295 | D20: =Hoja1!C14 -> 225 | E20: =Hoja1!L14 -> 0.98484848 | F20: =Hoja1!D14 -> 0 | G20: =Hoja1!E14 -> 8 | H20: =Hoja1!F14 -> 0 | I20: =Hoja1!H14/Hoja1!$H$20 -> 0.033427399 | K20: VONU | L20: =SUMIF('REPORTE DIARIO DE OPERACIONES'!C:C,"VONU",'REPORTE DIARIO DE OPERACIONES'!K:K) -> 350249 | M20: =SUMIF('REPORTE DIARIO DE OPERACIONES'!C:C,"VONU",'REPORTE DIARIO DE OPERACIONES'!M:M) -> 997 | N20: =SUMIF('REPORTE DIARIO DE OPERACIONES'!C:C,"VONU",'REPORTE DIARIO DE OPERACIONES'!S:S) -> 0 | O20: =M20/SUMIF('REPORTE DIARIO DE OPERACIONES'!C:C,"VONU",'REPORTE DIARIO DE OPERACIONES'!Q:Q) -> 0.94412879 | R20: • CPW-04: 23 hrs MMT correctivo
A21: =Hoja1!A15 -> G101V | B21: =Hoja1!H15 -> 38427 | C21: =Hoja1!B15 -> 110 | D21: =Hoja1!C15 -> 418 | E21: =Hoja1!L15 -> 1 | F21: =Hoja1!D15 -> 0 | G21: =Hoja1!E15 -> 0 | H21: =Hoja1!F15 -> 0 | I21: =Hoja1!H15/Hoja1!$H$20 -> 0.012257287 | K21: TOTAL | L21: =SUM(L19:L20) -> 3135033 | M21: =SUM(M19:M20) -> 5638 | N21: =SUM(N19:N20) -> 0 | O21: =AVERAGE(O19:O20) -> 0.81013258 | R21: • 42.7% de indisponibilidad
A22: =Hoja1!A16 -> G102J | B22: =Hoja1!H16 -> 85209 | C22: =Hoja1!B16 -> 110 | D22: =Hoja1!C16 -> 418 | E22: =Hoja1!L16 -> 1 | F22: =Hoja1!D16 -> 0 | G22: =Hoja1!E16 -> 0 | H22: =Hoja1!F16 -> 0 | I22: =Hoja1!H16/Hoja1!$H$20 -> 0.027179618
A23: =Hoja1!A17 -> G102K | B23: =Hoja1!H17 -> 91530 | C23: =Hoja1!B17 -> 120 | D23: =Hoja1!C17 -> 408 | E23: =Hoja1!L17 -> 1 | F23: =Hoja1!D17 -> 0 | G23: =Hoja1!E17 -> 0 | H23: =Hoja1!F17 -> 0 | I23: =Hoja1!H17/Hoja1!$H$20 -> 0.029195865 | K23: 🌎 RESUMEN POR CUENCA | R23: 💡 RECOMENDACIONES:
A24: =Hoja1!A18 -> JIN-01 | B24: =Hoja1!H18 -> 174954 | C24: =Hoja1!B18 -> 489 | D24: =Hoja1!C18 -> 23 | E24: =Hoja1!L18 -> 0.96969697 | F24: =Hoja1!D18 -> 0 | G24: =Hoja1!E18 -> 16 | H24: =Hoja1!F18 -> 0 | I24: =Hoja1!H18/Hoja1!$H$20 -> 0.055806111 | R24: • Inspección técnica CPW-04
A25: =Hoja1!A19 -> JIN-02 | B25: =Hoja1!H19 -> 175295 | C25: =Hoja1!B19 -> 508 | D25: =Hoja1!C19 -> 13 | E25: =Hoja1!L19 -> 0.98674242 | F25: =Hoja1!D19 -> 0 | G25: =Hoja1!E19 -> 7 | H25: =Hoja1!F19 -> 0 | I25: =Hoja1!H19/Hoja1!$H$20 -> 0.055914882 | K25: Cuenca | L25: KWH Total | M25: Hrs Operación | N25: Fallas | O25: Disponibilidad | R25: • Plan recuperación CUMMINS
A26: TOTAL | B26: =SUM(B11:B25) -> 3135033 | C26: =SUM(C11:C25) -> 5638 | D26: =SUM(D11:D25) -> 2209 | E26: =AVERAGE(E11:E25) -> 0.99078283 | F26: =SUM(F11:F25) -> 0 | G26: =SUM(G11:G25) -> 73 | H26: =SUM(H11:H25) -> 0 | I26: =SUM(I11:I25) -> 1 | K26: PUTN | L26: =SUMIF('REPORTE DIARIO DE OPERACIONES'!B:B,"PUTN",'REPORTE DIARIO DE OPERACIONES'!K:K) -> 3135033 | M26: =SUMIF('REPORTE DIARIO DE OPERACIONES'!B:B,"PUTN",'REPORTE DIARIO DE OPERACIONES'!M:M) -> 5638 | N26: =SUMIF('REPORTE DIARIO DE OPERACIONES'!B:B,"PUTN",'REPORTE DIARIO DE OPERACIONES'!S:S) -> 0 | O26: =M26/SUMIF('REPORTE DIARIO DE OPERACIONES'!B:B,"PUTN",'REPORTE DIARIO DE OPERACIONES'!Q:Q) -> 0.71186869 | R26: • Meta: Disponibilidad ≥75%
A29: 🏆 TOP 5 GENERADORES | E29: ⚠️ ANÁLISIS DE FALLAS
A31: Ranking | B31: Unidad | C31: KWH Generados | E31: Métrica | F31: Valor | G31: Unidad | H31: Descripción | I31: Estado
A32: 1 | B32: =INDEX(Hoja1!$A$5:$A$18,MATCH(LARGE(Hoja1!$H$5:$H$18,1),Hoja1!$H$5:$H$18,0)) -> CPW-05 | C32: =LARGE(Hoja1!$H$5:$H$18,1) -> 366816 | E32: Total Fallas | F32: =Hoja1!D19 -> 0 | G32: Fallas | H32: Suma total período | I32: =IF(F32<=2,"✅ Bueno",IF(F32<=5,"⚠️ Moderado","🔴 Crítico")) -> ✅ Bueno | R32: 14043
A33: 2 | B33: =INDEX(Hoja1!$A$5:$A$18,MATCH(LARGE(Hoja1!$H$5:$H$18,2),Hoja1!$H$5:$H$18,0)) -> CPW-04 | C33: =LARGE(Hoja1!$H$5:$H$18,2) -> 342171 | E33: Unidades c/Fallas | F33: =COUNTIF(Hoja1!D5:D19,">0") -> 0 | G33: Unidades | H33: Conteo >0 fallas | I33: =IF(F33<=2,"✅ Bueno",IF(F33<=4,"⚠️ Moderado","🔴 Crítico")) -> ✅ Bueno | R33: 78853
A34: 3 | B34: =INDEX(Hoja1!$A$5:$A$18,MATCH(LARGE(Hoja1!$H$5:$H$18,3),Hoja1!$H$5:$H$18,0)) -> CPW-06 | C34: =LARGE(Hoja1!$H$5:$H$18,3) -> 338404 | E34: Tasa de Fallas | F34: =Hoja1!D19/18 -> 0 | G34: Fallas/Unid | H34: Total/16 unidades | I34: =IF(F34<=0.15,"✅ Bueno",IF(F34<=0.3,"⚠️ Moderado","🔴 Crítico")) -> ✅ Bueno | R34: 40185
A35: 4 | B35: =INDEX(Hoja1!$A$5:$A$18,MATCH(LARGE(Hoja1!$H$5:$H$18,4),Hoja1!$H$5:$H$18,0)) -> CPW-01 | C35: =LARGE(Hoja1!$H$5:$H$18,4) -> 292328 | E35: MTBF | F35: =IF(Hoja1!D19>0,Hoja1!B19/Hoja1!D19,"N/A") -> N/A | G35: Horas | H35: Hrs Op / Fallas | I35: =IF(F35>2000,"✅ Excelente",IF(F35>1000,"⚠️ Aceptable","🔴 Bajo")) -> ✅ Excelente
A36: 5 | B36: =INDEX(Hoja1!$A$5:$A$18,MATCH(LARGE(Hoja1!$H$5:$H$18,5),Hoja1!$H$5:$H$18,0)) -> CPW-03 | C36: =LARGE(Hoja1!$H$5:$H$18,5) -> 287674 | E36: MTTR | F36: =IF(Hoja1!D19>0,Hoja1!F19/Hoja1!D19,"N/A") -> N/A | G36: Horas | H36: Hrs MMT Corr / Fallas | I36: =IF(F36<20,"✅ Bueno",IF(F36<40,"⚠️ Moderado","🔴 Alto")) -> 🔴 Alto
E37: Indisponibilidad | F37: =1-D6 -> 0.28813131 | G37: % | H37: 100% - Disponibilidad | I37: =IF(F37<0.3,"✅ Bueno",IF(F37<0.5,"⚠️ Regular","🔴 Crítico")) -> ✅ Bueno
K45: Unidad | L45: Fallas | M45: Unidad | N45: Fallas
K46: =IF(F11<>0,A11," ") | L46: =IF(K46<>0,F11," ") -> 0
K47: =IF(F12<>0,A12," ") | L47: =IF(K47<>0,F12," ") -> 0
K48: =IF(F13<>0,A13," ") | L48: =IF(K48<>0,F13," ") -> 0
K49: =IF(F14<>0,A14," ") | L49: =IF(K49<>0,F14," ") -> 0
K50: =IF(F15<>0,A15," ") | L50: =IF(K50<>0,F15," ") -> 0
K51: =IF(F16<>0,A16," ") | L51: =IF(K51<>0,F16," ") -> 0
K52: =IF(F17<>0,A17," ") | L52: =IF(K52<>0,F17," ") -> 0
...

Sheet Hoja2
A2: CPW-01 | B2: 435240 | C2: CPW-01 | D2: 371766 | F2: =(B2-D2)/B2 -> 0.14583678
A3: CPW-02 | B3: 397129 | C3: CPW-02 | D3: 407223 | F3: =(B3-D3)/B3 -> -0.025417434
A4: CPW-03 | B4: 409861 | C4: CPW-03 | D4: 394942 | F4: =(B4-D4)/B4 -> 0.036400145
A5: CPW-04 | B5: 438156 | C5: CPW-04 | D5: 585130 | F5: =(B5-D5)/B5 -> -0.33543761
A6: CPW-05 | B6: 431557 | C6: CPW-05 | D6: 587407 | F6: =(B6-D6)/B6 -> -0.36113422
A7: CPW-06 | B7: 457101 | C7: CPW-06 | D7: 560828 | F7: =(B7-D7)/B7 -> -0.22692359
A8: CPW-07 | B8: 439734 | C8: CPW-07 | D8: 401031 | F8: =(B8-D8)/B8 -> 0.088014572
A9: CPW-10 | B9: 224679 | C9: CPW-10 | D9: 172764 | F9: =(B9-D9)/B9 -> 0.23106298
A10: CPW-11 | B10: 132155 | F10: =(B10-D10)/B10 -> 1
A11: CPW-12 | B11: 150342 | F11: =(B11-D11)/B11 -> 1
A12: G101V | B12: 14043 | C12: G101V | D12: 8062 | F12: =(B12-D12)/B12 -> 0.42590615
A13: G102J | B13: 78853 | C13: G102J | D13: 47005 | F13: =(B13-D13)/B13 -> 0.40389078
A14: G102K | B14: 40185 | C14: G102K | D14: 54949 | F14: =(B14-D14)/B14 -> -0.36740077
A15: JIN-01 | B15: 256282 | C15: JIN-01 | D15: 268214 | F15: =(B15-D15)/B15 -> -0.046558088
A16: JIN-02 | B16: 226600 | C16: JIN-02 | D16: 248282 | F16: =(B16-D16)/B16 -> -0.095684025
D18: =B2-D2 -> 63474
